[2025-05-30 11:24:09,807: INFO: __init__: Welcome to custom log]
[2025-05-30 12:44:20,178: INFO: __init__: Welcome to custom log]
[2025-05-30 12:45:51,144: INFO: __init__: Welcome to custom log]
[2025-05-30 12:47:28,793: INFO: __init__: Welcome to custom log]
[2025-05-30 12:47:38,277: INFO: common: yaml file: config/config.yaml loaded successfully]
[2025-05-30 12:47:38,279: INFO: common: yaml file: params.yaml loaded successfully]
[2025-05-30 12:53:57,183: INFO: common: yaml file: config/config.yaml loaded successfully]
[2025-05-30 12:55:07,335: INFO: common: yaml file: config/config.yaml loaded successfully]
[2025-05-30 12:55:07,338: INFO: common: yaml file: params.yaml loaded successfully]
[2025-05-30 13:05:53,162: INFO: __init__: Welcome to custom log]
[2025-05-30 13:06:05,296: INFO: common: yaml file: config/config.yaml loaded successfully]
[2025-05-30 13:06:05,297: INFO: common: yaml file: params.yaml loaded successfully]
[2025-05-30 13:07:26,290: INFO: __init__: Welcome to custom log]
[2025-05-30 13:07:35,892: INFO: common: yaml file: config/config.yaml loaded successfully]
[2025-05-30 13:07:35,895: INFO: common: yaml file: params.yaml loaded successfully]
[2025-05-30 13:07:35,896: INFO: common: created directory at: artifacts]
[2025-05-30 13:07:35,897: INFO: common: created directory at: artifacts/data_ingestion]
[2025-05-30 13:39:29,832: INFO: __init__: Welcome to custom log]
[2025-05-30 13:45:02,253: INFO: common: yaml file: config/config.yaml loaded successfully]
[2025-05-30 13:45:02,256: INFO: common: yaml file: params.yaml loaded successfully]
[2025-05-30 13:45:02,257: INFO: common: created directory at: artifacts]
[2025-05-30 13:45:02,259: INFO: common: created directory at: artifacts/data_ingestion]
[2025-05-30 13:45:02,260: ERROR: 3469047994: Failed to download file due to: 'DataIngestionConfig' object has no attribute 'source_URL']
[2025-05-30 13:46:39,088: INFO: __init__: Welcome to custom log]
[2025-05-30 13:46:50,034: INFO: common: yaml file: config/config.yaml loaded successfully]
[2025-05-30 13:46:50,036: INFO: common: yaml file: params.yaml loaded successfully]
[2025-05-30 13:46:50,037: INFO: common: created directory at: artifacts]
[2025-05-30 13:46:50,038: INFO: common: created directory at: artifacts/data_ingestion]
[2025-05-30 13:46:50,039: INFO: 3469047994: Downloading data from https://drive.google.com/file/d/1wqlI7hsen8Q7wpjzs3pUeGlDZKqci4W-/view?usp=sharing into file artifacts/data_ingestion/data.zip]
[2025-05-30 13:51:12,204: INFO: 3469047994: Downloaded data from https://drive.google.com/file/d/1wqlI7hsen8Q7wpjzs3pUeGlDZKqci4W-/view?usp=sharing into file artifacts/data_ingestion/data.zip]
[2025-05-30 17:46:05,737: INFO: __init__: Welcome to custom log]
[2025-05-30 17:46:06,355: INFO: main: >>>>> stage Data Ingestion stage started <<<<<]
[2025-05-30 17:46:06,356: INFO: common: yaml file: config/config.yaml loaded successfully]
[2025-05-30 17:46:06,357: INFO: common: yaml file: params.yaml loaded successfully]
[2025-05-30 17:46:06,357: INFO: common: created directory at: artifacts]
[2025-05-30 17:46:06,357: INFO: common: created directory at: artifacts/data_ingestion]
[2025-05-30 17:46:06,357: INFO: data_ingestion: Downloading data from https://drive.google.com/file/d/1wqlI7hsen8Q7wpjzs3pUeGlDZKqci4W-/view?usp=sharing into file artifacts/data_ingestion/data.zip]
[2025-05-30 17:50:22,220: INFO: data_ingestion: Downloaded data from https://drive.google.com/file/d/1wqlI7hsen8Q7wpjzs3pUeGlDZKqci4W-/view?usp=sharing into file artifacts/data_ingestion/data.zip]
[2025-05-30 17:50:28,397: INFO: main: >>>>> stage Data Ingestion stage completed <<<<<

x==========x]
[2025-05-30 21:38:50,725: INFO: __init__: Welcome to custom log]
[2025-05-30 21:38:51,277: INFO: main: >>>>> stage Data Ingestion stage started <<<<<]
[2025-05-30 21:38:51,278: INFO: common: yaml file: config/config.yaml loaded successfully]
[2025-05-30 21:38:51,279: INFO: common: yaml file: params.yaml loaded successfully]
[2025-05-30 21:38:51,279: INFO: common: created directory at: artifacts]
[2025-05-30 21:38:51,279: INFO: common: created directory at: artifacts/data_ingestion]
[2025-05-30 21:38:51,279: INFO: data_ingestion: Downloading data from https://drive.google.com/file/d/1wqlI7hsen8Q7wpjzs3pUeGlDZKqci4W-/view?usp=sharing into file artifacts/data_ingestion/data.zip]
[2025-05-30 21:46:05,379: INFO: data_ingestion: Downloaded data from https://drive.google.com/file/d/1wqlI7hsen8Q7wpjzs3pUeGlDZKqci4W-/view?usp=sharing into file artifacts/data_ingestion/data.zip]
[2025-05-30 21:46:15,628: INFO: main: >>>>> stage Data Ingestion stage completed <<<<<

x==========x]
[2025-06-04 23:23:11,003: INFO: __init__: Welcome to custom log]
[2025-06-04 23:23:30,070: INFO: common: yaml file: config/config.yaml loaded successfully]
[2025-06-04 23:23:30,073: INFO: common: yaml file: params.yaml loaded successfully]
[2025-06-04 23:23:30,074: INFO: common: created directory at: artifacts]
[2025-06-04 23:23:30,075: INFO: common: created directory at: artifacts/prepare_base_model]
[2025-06-04 23:27:13,245: INFO: __init__: Welcome to custom log]
[2025-06-04 23:27:30,539: INFO: common: yaml file: config/config.yaml loaded successfully]
[2025-06-04 23:27:30,541: INFO: common: yaml file: params.yaml loaded successfully]
[2025-06-04 23:27:30,543: INFO: common: created directory at: artifacts]
[2025-06-04 23:27:30,544: INFO: common: created directory at: artifacts/prepare_base_model]
[2025-06-04 23:29:25,102: INFO: __init__: Welcome to custom log]
[2025-06-04 23:29:42,639: INFO: common: yaml file: config/config.yaml loaded successfully]
[2025-06-04 23:29:42,643: INFO: common: yaml file: params.yaml loaded successfully]
[2025-06-04 23:29:42,644: INFO: common: created directory at: artifacts]
[2025-06-04 23:29:42,645: INFO: common: created directory at: artifacts/prepare_base_model]
[2025-06-04 23:30:02,890: WARNING: saving_utils: Compiled the loaded model, but the compiled metrics have yet to be built. `model.compile_metrics` will be empty until you train or evaluate the model.]
[2025-06-04 23:30:03,094: WARNING: optimizer: At this time, the v2.11+ optimizer `tf.keras.optimizers.Adam` runs slowly on M1/M2 Macs, please use the legacy Keras optimizer instead, located at `tf.keras.optimizers.legacy.Adam`.]
[2025-06-04 23:30:03,104: WARNING: __init__: There is a known slowdown when using v2.11+ Keras optimizers on M1/M2 Macs. Falling back to the legacy Keras optimizer, i.e., `tf.keras.optimizers.legacy.Adam`.]
[2025-06-05 00:21:03,951: INFO: __init__: Welcome to custom log]
[2025-06-05 23:12:19,844: INFO: common: yaml file: config/config.yaml loaded successfully]
[2025-06-05 23:12:19,855: INFO: common: yaml file: params.yaml loaded successfully]
[2025-06-05 23:12:19,856: INFO: common: created directory at: artifacts]
[2025-06-05 23:12:19,857: INFO: common: created directory at: artifacts/training]
[2025-06-05 23:13:33,881: INFO: common: yaml file: config/config.yaml loaded successfully]
[2025-06-05 23:13:33,885: INFO: common: yaml file: params.yaml loaded successfully]
[2025-06-05 23:13:33,886: INFO: common: created directory at: artifacts]
[2025-06-05 23:13:33,887: INFO: common: created directory at: artifacts/training]
[2025-06-05 23:15:15,732: INFO: common: yaml file: config/config.yaml loaded successfully]
[2025-06-05 23:15:15,738: INFO: common: yaml file: params.yaml loaded successfully]
[2025-06-05 23:15:15,739: INFO: common: created directory at: artifacts]
[2025-06-05 23:15:15,739: INFO: common: created directory at: artifacts/training]
[2025-06-05 23:15:17,386: INFO: common: yaml file: config/config.yaml loaded successfully]
[2025-06-05 23:15:17,389: INFO: common: yaml file: params.yaml loaded successfully]
[2025-06-05 23:15:17,390: INFO: common: created directory at: artifacts]
[2025-06-05 23:15:17,392: INFO: common: created directory at: artifacts/training]
[2025-06-05 23:19:04,218: INFO: common: yaml file: config/config.yaml loaded successfully]
[2025-06-05 23:19:04,223: INFO: common: yaml file: params.yaml loaded successfully]
[2025-06-05 23:19:04,224: INFO: common: created directory at: artifacts]
[2025-06-05 23:19:04,225: INFO: common: created directory at: artifacts/training]
[2025-06-05 23:19:48,685: INFO: common: yaml file: config/config.yaml loaded successfully]
[2025-06-05 23:19:48,690: INFO: common: yaml file: params.yaml loaded successfully]
[2025-06-05 23:19:48,691: INFO: common: created directory at: artifacts]
[2025-06-05 23:19:48,692: INFO: common: created directory at: artifacts/training]
[2025-06-05 23:19:49,331: INFO: common: yaml file: config/config.yaml loaded successfully]
[2025-06-05 23:19:49,334: INFO: common: yaml file: params.yaml loaded successfully]
[2025-06-05 23:19:49,335: INFO: common: created directory at: artifacts]
[2025-06-05 23:19:49,336: INFO: common: created directory at: artifacts/training]
[2025-06-05 23:21:23,067: INFO: common: yaml file: config/config.yaml loaded successfully]
[2025-06-05 23:21:23,082: INFO: common: yaml file: params.yaml loaded successfully]
[2025-06-05 23:21:23,084: INFO: common: created directory at: artifacts]
[2025-06-05 23:21:23,085: INFO: common: created directory at: artifacts/training]
[2025-06-05 23:21:24,463: INFO: common: yaml file: config/config.yaml loaded successfully]
[2025-06-05 23:21:24,466: INFO: common: yaml file: params.yaml loaded successfully]
[2025-06-05 23:21:24,467: INFO: common: created directory at: artifacts]
[2025-06-05 23:21:24,469: INFO: common: created directory at: artifacts/training]
[2025-06-05 23:22:33,130: INFO: common: yaml file: config/config.yaml loaded successfully]
[2025-06-05 23:22:33,142: INFO: common: yaml file: params.yaml loaded successfully]
[2025-06-05 23:22:33,143: INFO: common: created directory at: artifacts]
[2025-06-05 23:22:33,143: INFO: common: created directory at: artifacts/training]
[2025-06-05 23:30:44,269: INFO: __init__: Welcome to custom log]
[2025-06-05 23:30:44,398: INFO: common: yaml file: config/config.yaml loaded successfully]
[2025-06-05 23:30:44,400: INFO: common: yaml file: params.yaml loaded successfully]
[2025-06-05 23:30:44,400: INFO: common: created directory at: artifacts]
[2025-06-05 23:30:44,401: INFO: common: created directory at: artifacts/training]
[2025-06-06 23:30:08,702: INFO: __init__: Welcome to custom log]
[2025-06-06 23:30:37,297: INFO: common: yaml file: config/config.yaml loaded successfully]
[2025-06-06 23:30:37,303: INFO: common: yaml file: params.yaml loaded successfully]
[2025-06-06 23:30:37,304: INFO: common: created directory at: artifacts]
[2025-06-06 23:30:37,306: INFO: common: created directory at: artifacts/training]
[2025-06-07 21:37:47,069: INFO: __init__: Welcome to custom log]
[2025-06-07 21:37:51,392: INFO: main: >>>>> stage Data Ingestion stage started <<<<<]
[2025-06-07 21:37:51,394: INFO: common: yaml file: config/config.yaml loaded successfully]
[2025-06-07 21:37:51,396: INFO: common: yaml file: params.yaml loaded successfully]
[2025-06-07 21:37:51,396: INFO: common: created directory at: artifacts]
[2025-06-07 21:37:51,396: ERROR: main: 'ConfigurationManager' object has no attribute 'get_data_ingestion_config']
Traceback (most recent call last):
  File "main.py", line 10, in <module>
    data_ingestion_pipeline.main()
  File "/Users/sushraireddy/Desktop/Kidney-Disease-Classfication/Kidney-Disease-Classfication/src/cnnClassifier/pipeline/stage_01_data_ingestion.py", line 12, in main
    data_ingestion_config = config.get_data_ingestion_config()
AttributeError: 'ConfigurationManager' object has no attribute 'get_data_ingestion_config'
[2025-06-07 21:40:55,307: INFO: __init__: Welcome to custom log]
[2025-06-07 21:40:59,356: INFO: main: >>>>> stage Data Ingestion stage started <<<<<]
[2025-06-07 21:40:59,358: INFO: common: yaml file: config/config.yaml loaded successfully]
[2025-06-07 21:40:59,359: INFO: common: yaml file: params.yaml loaded successfully]
[2025-06-07 21:40:59,359: INFO: common: created directory at: artifacts]
[2025-06-07 21:40:59,359: INFO: common: created directory at: artifacts/data_ingestion]
[2025-06-07 21:40:59,359: INFO: data_ingestion: Downloading data from https://drive.google.com/file/d/1wqlI7hsen8Q7wpjzs3pUeGlDZKqci4W-/view?usp=sharing into file artifacts/data_ingestion/data.zip]
[2025-06-07 21:45:40,816: INFO: data_ingestion: Downloaded data from https://drive.google.com/file/d/1wqlI7hsen8Q7wpjzs3pUeGlDZKqci4W-/view?usp=sharing into file artifacts/data_ingestion/data.zip]
[2025-06-07 21:45:54,837: INFO: main: >>>>> stage Data Ingestion stage completed <<<<<

x==========x]
[2025-06-07 21:45:54,838: INFO: main: >>>>> stage Prepare Base Model Stage started <<<<<]
[2025-06-07 21:45:54,863: INFO: common: yaml file: config/config.yaml loaded successfully]
[2025-06-07 21:45:55,207: INFO: common: yaml file: params.yaml loaded successfully]
[2025-06-07 21:45:55,207: INFO: common: created directory at: artifacts]
[2025-06-07 21:45:55,208: INFO: common: created directory at: artifacts/prepare_base_model]
[2025-06-07 21:45:55,209: ERROR: main: "'ConfigBox' object has no attribute 'base_model_name'"]
Traceback (most recent call last):
  File "/Users/sushraireddy/Desktop/Kidney-Disease-Classfication/kidney310/lib/python3.8/site-packages/box/box.py", line 503, in __getitem__
    return super().__getitem__(item)
KeyError: 'base_model_name'

The above exception was the direct cause of the following exception:

Traceback (most recent call last):
  File "/Users/sushraireddy/Desktop/Kidney-Disease-Classfication/kidney310/lib/python3.8/site-packages/box/box.py", line 536, in __getattr__
    value = self.__getitem__(item, _ignore_default=True)
  File "/Users/sushraireddy/Desktop/Kidney-Disease-Classfication/kidney310/lib/python3.8/site-packages/box/box.py", line 524, in __getitem__
    raise BoxKeyError(str(err)) from _exception_cause(err)
box.exceptions.BoxKeyError: "'base_model_name'"

During handling of the above exception, another exception occurred:

Traceback (most recent call last):
  File "/Users/sushraireddy/Desktop/Kidney-Disease-Classfication/kidney310/lib/python3.8/site-packages/box/box.py", line 538, in __getattr__
    value = object.__getattribute__(self, item)
AttributeError: 'ConfigBox' object has no attribute 'base_model_name'

The above exception was the direct cause of the following exception:

Traceback (most recent call last):
  File "/Users/sushraireddy/Desktop/Kidney-Disease-Classfication/kidney310/lib/python3.8/site-packages/box/config_box.py", line 28, in __getattr__
    return super().__getattr__(item)
  File "/Users/sushraireddy/Desktop/Kidney-Disease-Classfication/kidney310/lib/python3.8/site-packages/box/box.py", line 552, in __getattr__
    raise BoxKeyError(str(err)) from _exception_cause(err)
box.exceptions.BoxKeyError: "'ConfigBox' object has no attribute 'base_model_name'"

During handling of the above exception, another exception occurred:

Traceback (most recent call last):
  File "/Users/sushraireddy/Desktop/Kidney-Disease-Classfication/kidney310/lib/python3.8/site-packages/box/box.py", line 503, in __getitem__
    return super().__getitem__(item)
KeyError: 'base_model_name'

The above exception was the direct cause of the following exception:

Traceback (most recent call last):
  File "/Users/sushraireddy/Desktop/Kidney-Disease-Classfication/kidney310/lib/python3.8/site-packages/box/box.py", line 536, in __getattr__
    value = self.__getitem__(item, _ignore_default=True)
  File "/Users/sushraireddy/Desktop/Kidney-Disease-Classfication/kidney310/lib/python3.8/site-packages/box/box.py", line 524, in __getitem__
    raise BoxKeyError(str(err)) from _exception_cause(err)
box.exceptions.BoxKeyError: "'base_model_name'"

During handling of the above exception, another exception occurred:

Traceback (most recent call last):
  File "/Users/sushraireddy/Desktop/Kidney-Disease-Classfication/kidney310/lib/python3.8/site-packages/box/box.py", line 538, in __getattr__
    value = object.__getattribute__(self, item)
AttributeError: 'ConfigBox' object has no attribute 'base_model_name'

The above exception was the direct cause of the following exception:

Traceback (most recent call last):
  File "main.py", line 21, in <module>
    prepare_base_model_pipeline.main()
  File "/Users/sushraireddy/Desktop/Kidney-Disease-Classfication/Kidney-Disease-Classfication/src/cnnClassifier/pipeline/stage_02_prepare_base_model.py", line 13, in main
    prepare_base_model_config = config_manager.get_prepare_base_model_config()
  File "/Users/sushraireddy/Desktop/Kidney-Disease-Classfication/Kidney-Disease-Classfication/src/cnnClassifier/config/configuration.py", line 39, in get_prepare_base_model_config
    base_model_name=Path(config.base_model_name),
  File "/Users/sushraireddy/Desktop/Kidney-Disease-Classfication/kidney310/lib/python3.8/site-packages/box/config_box.py", line 30, in __getattr__
    return super().__getattr__(item.lower())
  File "/Users/sushraireddy/Desktop/Kidney-Disease-Classfication/kidney310/lib/python3.8/site-packages/box/box.py", line 552, in __getattr__
    raise BoxKeyError(str(err)) from _exception_cause(err)
box.exceptions.BoxKeyError: "'ConfigBox' object has no attribute 'base_model_name'"
[2025-06-07 21:48:11,761: INFO: __init__: Welcome to custom log]
[2025-06-07 21:48:15,862: INFO: main: >>>>> stage Data Ingestion stage started <<<<<]
[2025-06-07 21:48:15,864: INFO: common: yaml file: config/config.yaml loaded successfully]
[2025-06-07 21:48:15,866: INFO: common: yaml file: params.yaml loaded successfully]
[2025-06-07 21:48:15,866: INFO: common: created directory at: artifacts]
[2025-06-07 21:48:15,866: INFO: common: created directory at: artifacts/data_ingestion]
[2025-06-07 21:48:15,866: INFO: data_ingestion: Downloading data from https://drive.google.com/file/d/1wqlI7hsen8Q7wpjzs3pUeGlDZKqci4W-/view?usp=sharing into file artifacts/data_ingestion/data.zip]
[2025-06-07 21:52:54,077: INFO: data_ingestion: Downloaded data from https://drive.google.com/file/d/1wqlI7hsen8Q7wpjzs3pUeGlDZKqci4W-/view?usp=sharing into file artifacts/data_ingestion/data.zip]
[2025-06-07 21:53:44,564: INFO: __init__: Welcome to custom log]
[2025-06-07 21:53:48,852: INFO: main: >>>>> stage Data Ingestion stage started <<<<<]
[2025-06-07 21:53:48,854: INFO: common: yaml file: config/config.yaml loaded successfully]
[2025-06-07 21:53:48,856: INFO: common: yaml file: params.yaml loaded successfully]
[2025-06-07 21:53:48,856: INFO: common: created directory at: artifacts]
[2025-06-07 21:53:48,857: INFO: common: created directory at: artifacts/data_ingestion]
[2025-06-07 21:53:48,857: INFO: data_ingestion: Downloading data from https://drive.google.com/file/d/1wqlI7hsen8Q7wpjzs3pUeGlDZKqci4W-/view?usp=sharing into file artifacts/data_ingestion/data.zip]
[2025-06-07 21:58:23,748: INFO: data_ingestion: Downloaded data from https://drive.google.com/file/d/1wqlI7hsen8Q7wpjzs3pUeGlDZKqci4W-/view?usp=sharing into file artifacts/data_ingestion/data.zip]
[2025-06-07 21:58:33,241: INFO: main: >>>>> stage Data Ingestion stage completed <<<<<

x==========x]
[2025-06-07 21:58:33,241: INFO: main: >>>>> stage Prepare Base Model Stage started <<<<<]
[2025-06-07 21:58:33,244: INFO: common: yaml file: config/config.yaml loaded successfully]
[2025-06-07 21:58:33,246: INFO: common: yaml file: params.yaml loaded successfully]
[2025-06-07 21:58:33,246: INFO: common: created directory at: artifacts]
[2025-06-07 21:58:33,246: INFO: common: created directory at: artifacts/prepare_base_model]
[2025-06-07 21:58:33,246: ERROR: main: "'ConfigBox' object has no attribute 'update_base_model'"]
Traceback (most recent call last):
  File "/Users/sushraireddy/Desktop/Kidney-Disease-Classfication/kidney310/lib/python3.8/site-packages/box/box.py", line 503, in __getitem__
    return super().__getitem__(item)
KeyError: 'update_base_model'

The above exception was the direct cause of the following exception:

Traceback (most recent call last):
  File "/Users/sushraireddy/Desktop/Kidney-Disease-Classfication/kidney310/lib/python3.8/site-packages/box/box.py", line 536, in __getattr__
    value = self.__getitem__(item, _ignore_default=True)
  File "/Users/sushraireddy/Desktop/Kidney-Disease-Classfication/kidney310/lib/python3.8/site-packages/box/box.py", line 524, in __getitem__
    raise BoxKeyError(str(err)) from _exception_cause(err)
box.exceptions.BoxKeyError: "'update_base_model'"

During handling of the above exception, another exception occurred:

Traceback (most recent call last):
  File "/Users/sushraireddy/Desktop/Kidney-Disease-Classfication/kidney310/lib/python3.8/site-packages/box/box.py", line 538, in __getattr__
    value = object.__getattribute__(self, item)
AttributeError: 'ConfigBox' object has no attribute 'update_base_model'

The above exception was the direct cause of the following exception:

Traceback (most recent call last):
  File "/Users/sushraireddy/Desktop/Kidney-Disease-Classfication/kidney310/lib/python3.8/site-packages/box/config_box.py", line 28, in __getattr__
    return super().__getattr__(item)
  File "/Users/sushraireddy/Desktop/Kidney-Disease-Classfication/kidney310/lib/python3.8/site-packages/box/box.py", line 552, in __getattr__
    raise BoxKeyError(str(err)) from _exception_cause(err)
box.exceptions.BoxKeyError: "'ConfigBox' object has no attribute 'update_base_model'"

During handling of the above exception, another exception occurred:

Traceback (most recent call last):
  File "/Users/sushraireddy/Desktop/Kidney-Disease-Classfication/kidney310/lib/python3.8/site-packages/box/box.py", line 503, in __getitem__
    return super().__getitem__(item)
KeyError: 'update_base_model'

The above exception was the direct cause of the following exception:

Traceback (most recent call last):
  File "/Users/sushraireddy/Desktop/Kidney-Disease-Classfication/kidney310/lib/python3.8/site-packages/box/box.py", line 536, in __getattr__
    value = self.__getitem__(item, _ignore_default=True)
  File "/Users/sushraireddy/Desktop/Kidney-Disease-Classfication/kidney310/lib/python3.8/site-packages/box/box.py", line 524, in __getitem__
    raise BoxKeyError(str(err)) from _exception_cause(err)
box.exceptions.BoxKeyError: "'update_base_model'"

During handling of the above exception, another exception occurred:

Traceback (most recent call last):
  File "/Users/sushraireddy/Desktop/Kidney-Disease-Classfication/kidney310/lib/python3.8/site-packages/box/box.py", line 538, in __getattr__
    value = object.__getattribute__(self, item)
AttributeError: 'ConfigBox' object has no attribute 'update_base_model'

The above exception was the direct cause of the following exception:

Traceback (most recent call last):
  File "main.py", line 21, in <module>
    prepare_base_model_pipeline.main()
  File "/Users/sushraireddy/Desktop/Kidney-Disease-Classfication/Kidney-Disease-Classfication/src/cnnClassifier/pipeline/stage_02_prepare_base_model.py", line 13, in main
    prepare_base_model_config = config_manager.get_prepare_base_model_config()
  File "/Users/sushraireddy/Desktop/Kidney-Disease-Classfication/Kidney-Disease-Classfication/src/cnnClassifier/config/configuration.py", line 40, in get_prepare_base_model_config
    update_base_model=Path(config.update_base_model),
  File "/Users/sushraireddy/Desktop/Kidney-Disease-Classfication/kidney310/lib/python3.8/site-packages/box/config_box.py", line 30, in __getattr__
    return super().__getattr__(item.lower())
  File "/Users/sushraireddy/Desktop/Kidney-Disease-Classfication/kidney310/lib/python3.8/site-packages/box/box.py", line 552, in __getattr__
    raise BoxKeyError(str(err)) from _exception_cause(err)
box.exceptions.BoxKeyError: "'ConfigBox' object has no attribute 'update_base_model'"
[2025-06-07 22:15:59,642: INFO: __init__: Welcome to custom log]
[2025-06-07 22:16:03,913: INFO: main: >>>>> stage Data Ingestion stage started <<<<<]
[2025-06-07 22:16:03,915: INFO: common: yaml file: config/config.yaml loaded successfully]
[2025-06-07 22:16:03,917: INFO: common: yaml file: params.yaml loaded successfully]
[2025-06-07 22:16:03,917: INFO: common: created directory at: artifacts]
[2025-06-07 22:16:03,917: INFO: common: created directory at: artifacts/data_ingestion]
[2025-06-07 22:16:03,917: INFO: data_ingestion: Downloading data from https://drive.google.com/file/d/1wqlI7hsen8Q7wpjzs3pUeGlDZKqci4W-/view?usp=sharing into file artifacts/data_ingestion/data.zip]
[2025-06-07 22:20:57,305: INFO: data_ingestion: Downloaded data from https://drive.google.com/file/d/1wqlI7hsen8Q7wpjzs3pUeGlDZKqci4W-/view?usp=sharing into file artifacts/data_ingestion/data.zip]
[2025-06-07 22:21:08,019: INFO: main: >>>>> stage Data Ingestion stage completed <<<<<

x==========x]
[2025-06-07 22:21:08,019: INFO: main: >>>>> stage Prepare Base Model Stage started <<<<<]
[2025-06-07 22:21:08,024: INFO: common: yaml file: config/config.yaml loaded successfully]
[2025-06-07 22:21:08,025: INFO: common: yaml file: params.yaml loaded successfully]
[2025-06-07 22:21:08,025: INFO: common: created directory at: artifacts]
[2025-06-07 22:21:08,025: INFO: common: created directory at: artifacts/prepare_base_model]
[2025-06-07 22:21:08,026: ERROR: main: __init__() got an unexpected keyword argument 'base_model_name']
Traceback (most recent call last):
  File "main.py", line 21, in <module>
    prepare_base_model_pipeline.main()
  File "/Users/sushraireddy/Desktop/Kidney-Disease-Classfication/Kidney-Disease-Classfication/src/cnnClassifier/pipeline/stage_02_prepare_base_model.py", line 13, in main
    prepare_base_model_config = config_manager.get_prepare_base_model_config()
  File "/Users/sushraireddy/Desktop/Kidney-Disease-Classfication/Kidney-Disease-Classfication/src/cnnClassifier/config/configuration.py", line 37, in get_prepare_base_model_config
    prepare_base_model_config = PrepareBaseModelConfig(
TypeError: __init__() got an unexpected keyword argument 'base_model_name'
[2025-06-07 22:32:08,388: INFO: __init__: Welcome to custom log]
[2025-06-07 22:32:13,918: INFO: main: >>>>> stage Data Ingestion stage started <<<<<]
[2025-06-07 22:32:13,922: INFO: common: yaml file: config/config.yaml loaded successfully]
[2025-06-07 22:32:13,925: INFO: common: yaml file: params.yaml loaded successfully]
[2025-06-07 22:32:13,925: INFO: common: created directory at: artifacts]
[2025-06-07 22:32:13,926: INFO: common: created directory at: artifacts/data_ingestion]
[2025-06-07 22:32:13,926: INFO: data_ingestion: Downloading data from https://drive.google.com/file/d/1wqlI7hsen8Q7wpjzs3pUeGlDZKqci4W-/view?usp=sharing into file artifacts/data_ingestion/data.zip]
[2025-06-07 22:38:47,840: INFO: data_ingestion: Downloaded data from https://drive.google.com/file/d/1wqlI7hsen8Q7wpjzs3pUeGlDZKqci4W-/view?usp=sharing into file artifacts/data_ingestion/data.zip]
[2025-06-07 22:38:57,534: INFO: main: >>>>> stage Data Ingestion stage completed <<<<<

x==========x]
[2025-06-07 22:38:57,535: INFO: main: >>>>> stage Prepare Base Model Stage started <<<<<]
[2025-06-07 22:38:57,538: INFO: common: yaml file: config/config.yaml loaded successfully]
[2025-06-07 22:38:57,540: INFO: common: yaml file: params.yaml loaded successfully]
[2025-06-07 22:38:57,540: INFO: common: created directory at: artifacts]
[2025-06-07 22:38:57,540: INFO: common: created directory at: artifacts/prepare_base_model]
[2025-06-07 22:38:59,113: WARNING: saving_utils: Compiled the loaded model, but the compiled metrics have yet to be built. `model.compile_metrics` will be empty until you train or evaluate the model.]
[2025-06-07 22:38:59,254: WARNING: optimizer: At this time, the v2.11+ optimizer `tf.keras.optimizers.Adam` runs slowly on M1/M2 Macs, please use the legacy Keras optimizer instead, located at `tf.keras.optimizers.legacy.Adam`.]
[2025-06-07 22:38:59,257: WARNING: __init__: There is a known slowdown when using v2.11+ Keras optimizers on M1/M2 Macs. Falling back to the legacy Keras optimizer, i.e., `tf.keras.optimizers.legacy.Adam`.]
[2025-06-07 22:38:59,397: INFO: main: >>>>> stage Prepare Base Model Stage completed <<<<<

x==========x]
[2025-06-07 22:38:59,397: INFO: main: >>>>> stage Model Training Stage started <<<<<]
[2025-06-07 22:38:59,399: INFO: common: yaml file: config/config.yaml loaded successfully]
[2025-06-07 22:38:59,400: INFO: common: yaml file: params.yaml loaded successfully]
[2025-06-07 22:38:59,401: INFO: common: created directory at: artifacts]
[2025-06-07 22:38:59,401: INFO: common: created directory at: artifacts/training]
[2025-06-07 22:38:59,401: ERROR: main: __init__() got an unexpected keyword argument 'params_is_augmentation']
Traceback (most recent call last):
  File "main.py", line 31, in <module>
    model_training_pipeline.main()
  File "/Users/sushraireddy/Desktop/Kidney-Disease-Classfication/Kidney-Disease-Classfication/src/cnnClassifier/pipeline/stage_03_model_training.py", line 12, in main
    training_config = config.get_training_config()
  File "/Users/sushraireddy/Desktop/Kidney-Disease-Classfication/Kidney-Disease-Classfication/src/cnnClassifier/config/configuration.py", line 63, in get_training_config
    training_config = TrainingConfig(
TypeError: __init__() got an unexpected keyword argument 'params_is_augmentation'
[2025-06-07 22:43:29,683: INFO: __init__: Welcome to custom log]
[2025-06-07 22:43:33,945: INFO: main: >>>>> stage Data Ingestion stage started <<<<<]
[2025-06-07 22:43:33,947: INFO: common: yaml file: config/config.yaml loaded successfully]
[2025-06-07 22:43:33,948: INFO: common: yaml file: params.yaml loaded successfully]
[2025-06-07 22:43:33,948: INFO: common: created directory at: artifacts]
[2025-06-07 22:43:33,949: INFO: common: created directory at: artifacts/data_ingestion]
[2025-06-07 22:43:33,949: INFO: data_ingestion: Downloading data from https://drive.google.com/file/d/1wqlI7hsen8Q7wpjzs3pUeGlDZKqci4W-/view?usp=sharing into file artifacts/data_ingestion/data.zip]
[2025-06-07 22:48:02,235: INFO: data_ingestion: Downloaded data from https://drive.google.com/file/d/1wqlI7hsen8Q7wpjzs3pUeGlDZKqci4W-/view?usp=sharing into file artifacts/data_ingestion/data.zip]
[2025-06-07 22:48:12,346: INFO: main: >>>>> stage Data Ingestion stage completed <<<<<

x==========x]
[2025-06-07 22:48:12,347: INFO: main: >>>>> stage Prepare Base Model Stage started <<<<<]
[2025-06-07 22:48:12,350: INFO: common: yaml file: config/config.yaml loaded successfully]
[2025-06-07 22:48:12,352: INFO: common: yaml file: params.yaml loaded successfully]
[2025-06-07 22:48:12,352: INFO: common: created directory at: artifacts]
[2025-06-07 22:48:12,352: INFO: common: created directory at: artifacts/prepare_base_model]
[2025-06-07 22:48:13,233: WARNING: saving_utils: Compiled the loaded model, but the compiled metrics have yet to be built. `model.compile_metrics` will be empty until you train or evaluate the model.]
[2025-06-07 22:48:13,338: WARNING: optimizer: At this time, the v2.11+ optimizer `tf.keras.optimizers.Adam` runs slowly on M1/M2 Macs, please use the legacy Keras optimizer instead, located at `tf.keras.optimizers.legacy.Adam`.]
[2025-06-07 22:48:13,340: WARNING: __init__: There is a known slowdown when using v2.11+ Keras optimizers on M1/M2 Macs. Falling back to the legacy Keras optimizer, i.e., `tf.keras.optimizers.legacy.Adam`.]
[2025-06-07 22:48:13,420: INFO: main: >>>>> stage Prepare Base Model Stage completed <<<<<

x==========x]
[2025-06-07 22:48:13,421: INFO: main: >>>>> stage Model Training Stage started <<<<<]
[2025-06-07 22:48:13,423: INFO: common: yaml file: config/config.yaml loaded successfully]
[2025-06-07 22:48:13,425: INFO: common: yaml file: params.yaml loaded successfully]
[2025-06-07 22:48:13,425: INFO: common: created directory at: artifacts]
[2025-06-07 22:48:13,425: INFO: common: created directory at: artifacts/training]
[2025-06-07 22:48:13,425: ERROR: main: __init__() got an unexpected keyword argument 'params_is_augumentation']
Traceback (most recent call last):
  File "main.py", line 31, in <module>
    model_training_pipeline.main()
  File "/Users/sushraireddy/Desktop/Kidney-Disease-Classfication/Kidney-Disease-Classfication/src/cnnClassifier/pipeline/stage_03_model_training.py", line 12, in main
    training_config = config.get_training_config()
  File "/Users/sushraireddy/Desktop/Kidney-Disease-Classfication/Kidney-Disease-Classfication/src/cnnClassifier/config/configuration.py", line 63, in get_training_config
    training_config = TrainingConfig(
TypeError: __init__() got an unexpected keyword argument 'params_is_augumentation'
[2025-06-07 22:51:46,270: INFO: __init__: Welcome to custom log]
[2025-06-07 22:51:51,027: INFO: main: >>>>> stage Data Ingestion stage started <<<<<]
[2025-06-07 22:51:51,030: INFO: common: yaml file: config/config.yaml loaded successfully]
[2025-06-07 22:51:51,031: INFO: common: yaml file: params.yaml loaded successfully]
[2025-06-07 22:51:51,031: INFO: common: created directory at: artifacts]
[2025-06-07 22:51:51,031: INFO: common: created directory at: artifacts/data_ingestion]
[2025-06-07 22:51:51,031: INFO: data_ingestion: Downloading data from https://drive.google.com/file/d/1wqlI7hsen8Q7wpjzs3pUeGlDZKqci4W-/view?usp=sharing into file artifacts/data_ingestion/data.zip]
[2025-06-07 22:56:20,099: INFO: data_ingestion: Downloaded data from https://drive.google.com/file/d/1wqlI7hsen8Q7wpjzs3pUeGlDZKqci4W-/view?usp=sharing into file artifacts/data_ingestion/data.zip]
[2025-06-07 22:56:34,602: INFO: main: >>>>> stage Data Ingestion stage completed <<<<<

x==========x]
[2025-06-07 22:56:34,603: INFO: main: >>>>> stage Prepare Base Model Stage started <<<<<]
[2025-06-07 22:56:34,609: INFO: common: yaml file: config/config.yaml loaded successfully]
[2025-06-07 22:56:34,612: INFO: common: yaml file: params.yaml loaded successfully]
[2025-06-07 22:56:34,612: INFO: common: created directory at: artifacts]
[2025-06-07 22:56:34,612: INFO: common: created directory at: artifacts/prepare_base_model]
[2025-06-07 22:56:35,737: WARNING: saving_utils: Compiled the loaded model, but the compiled metrics have yet to be built. `model.compile_metrics` will be empty until you train or evaluate the model.]
[2025-06-07 22:56:35,848: WARNING: optimizer: At this time, the v2.11+ optimizer `tf.keras.optimizers.Adam` runs slowly on M1/M2 Macs, please use the legacy Keras optimizer instead, located at `tf.keras.optimizers.legacy.Adam`.]
[2025-06-07 22:56:35,851: WARNING: __init__: There is a known slowdown when using v2.11+ Keras optimizers on M1/M2 Macs. Falling back to the legacy Keras optimizer, i.e., `tf.keras.optimizers.legacy.Adam`.]
[2025-06-07 22:56:35,934: INFO: main: >>>>> stage Prepare Base Model Stage completed <<<<<

x==========x]
[2025-06-07 22:56:35,934: INFO: main: >>>>> stage Model Training Stage started <<<<<]
[2025-06-07 22:56:35,937: INFO: common: yaml file: config/config.yaml loaded successfully]
[2025-06-07 22:56:35,938: INFO: common: yaml file: params.yaml loaded successfully]
[2025-06-07 22:56:35,938: INFO: common: created directory at: artifacts]
[2025-06-07 22:56:35,938: INFO: common: created directory at: artifacts/training]
[2025-06-07 22:56:36,128: ERROR: main: [Errno 2] No such file or directory: 'artifacts/data_ingestion/kidney-ct-scan-image']
Traceback (most recent call last):
  File "main.py", line 31, in <module>
    model_training_pipeline.main()
  File "/Users/sushraireddy/Desktop/Kidney-Disease-Classfication/Kidney-Disease-Classfication/src/cnnClassifier/pipeline/stage_03_model_training.py", line 15, in main
    training.train_valid_generator()
  File "/Users/sushraireddy/Desktop/Kidney-Disease-Classfication/Kidney-Disease-Classfication/src/cnnClassifier/components/model_training.py", line 40, in train_valid_generator
    self.valid_generator = valid_datagenerator.flow_from_directory(
  File "/Users/sushraireddy/Desktop/Kidney-Disease-Classfication/kidney310/lib/python3.8/site-packages/keras/preprocessing/image.py", line 1648, in flow_from_directory
    return DirectoryIterator(
  File "/Users/sushraireddy/Desktop/Kidney-Disease-Classfication/kidney310/lib/python3.8/site-packages/keras/preprocessing/image.py", line 563, in __init__
    for subdir in sorted(os.listdir(directory)):
FileNotFoundError: [Errno 2] No such file or directory: 'artifacts/data_ingestion/kidney-ct-scan-image'
[2025-06-07 23:01:12,361: INFO: __init__: Welcome to custom log]
[2025-06-07 23:01:21,112: INFO: main: >>>>> stage Data Ingestion stage started <<<<<]
[2025-06-07 23:01:21,116: INFO: common: yaml file: config/config.yaml loaded successfully]
[2025-06-07 23:01:21,119: INFO: common: yaml file: params.yaml loaded successfully]
[2025-06-07 23:01:21,120: INFO: common: created directory at: artifacts]
[2025-06-07 23:01:21,120: INFO: common: created directory at: artifacts/data_ingestion]
[2025-06-07 23:01:21,120: INFO: data_ingestion: Downloading data from https://drive.google.com/file/d/1wqlI7hsen8Q7wpjzs3pUeGlDZKqci4W-/view?usp=sharing into file artifacts/data_ingestion/data.zip]
[2025-06-07 23:05:07,519: INFO: __init__: Welcome to custom log]
[2025-06-07 23:05:11,847: INFO: main: >>>>> stage Data Ingestion stage started <<<<<]
[2025-06-07 23:05:11,850: INFO: common: yaml file: config/config.yaml loaded successfully]
[2025-06-07 23:05:11,851: INFO: common: yaml file: params.yaml loaded successfully]
[2025-06-07 23:05:11,852: INFO: common: created directory at: artifacts]
[2025-06-07 23:05:11,852: INFO: common: created directory at: artifacts/data_ingestion]
[2025-06-07 23:05:11,852: INFO: data_ingestion: Downloading data from https://drive.google.com/file/d/1wqlI7hsen8Q7wpjzs3pUeGlDZKqci4W-/view?usp=sharing into file artifacts/data_ingestion/data.zip]
[2025-06-07 23:09:46,007: INFO: data_ingestion: Downloaded data from https://drive.google.com/file/d/1wqlI7hsen8Q7wpjzs3pUeGlDZKqci4W-/view?usp=sharing into file artifacts/data_ingestion/data.zip]
[2025-06-07 23:09:55,556: INFO: main: >>>>> stage Data Ingestion stage completed <<<<<

x==========x]
[2025-06-07 23:09:55,556: INFO: main: >>>>> stage Prepare Base Model Stage started <<<<<]
[2025-06-07 23:09:55,559: INFO: common: yaml file: config/config.yaml loaded successfully]
[2025-06-07 23:09:55,561: INFO: common: yaml file: params.yaml loaded successfully]
[2025-06-07 23:09:55,561: INFO: common: created directory at: artifacts]
[2025-06-07 23:09:55,561: INFO: common: created directory at: artifacts/prepare_base_model]
[2025-06-07 23:09:56,473: WARNING: saving_utils: Compiled the loaded model, but the compiled metrics have yet to be built. `model.compile_metrics` will be empty until you train or evaluate the model.]
[2025-06-07 23:09:56,581: WARNING: optimizer: At this time, the v2.11+ optimizer `tf.keras.optimizers.Adam` runs slowly on M1/M2 Macs, please use the legacy Keras optimizer instead, located at `tf.keras.optimizers.legacy.Adam`.]
[2025-06-07 23:09:56,584: WARNING: __init__: There is a known slowdown when using v2.11+ Keras optimizers on M1/M2 Macs. Falling back to the legacy Keras optimizer, i.e., `tf.keras.optimizers.legacy.Adam`.]
[2025-06-07 23:09:56,664: INFO: main: >>>>> stage Prepare Base Model Stage completed <<<<<

x==========x]
[2025-06-07 23:09:56,664: INFO: main: >>>>> stage Model Training Stage started <<<<<]
[2025-06-07 23:09:56,666: INFO: common: yaml file: config/config.yaml loaded successfully]
[2025-06-07 23:09:56,668: INFO: common: yaml file: params.yaml loaded successfully]
[2025-06-07 23:09:56,668: INFO: common: created directory at: artifacts]
[2025-06-07 23:09:56,668: INFO: common: created directory at: artifacts/training]
[2025-06-07 23:09:56,841: ERROR: main: [Errno 2] No such file or directory: 'artifacts/data_ingestion/kidney-ct-scan-image']
Traceback (most recent call last):
  File "main.py", line 31, in <module>
    model_training_pipeline.main()
  File "/Users/sushraireddy/Desktop/Kidney-Disease-Classfication/Kidney-Disease-Classfication/src/cnnClassifier/pipeline/stage_03_model_training.py", line 15, in main
    training.train_valid_generator()
  File "/Users/sushraireddy/Desktop/Kidney-Disease-Classfication/Kidney-Disease-Classfication/src/cnnClassifier/components/model_training.py", line 40, in train_valid_generator
    self.valid_generator = valid_datagenerator.flow_from_directory(
  File "/Users/sushraireddy/Desktop/Kidney-Disease-Classfication/kidney310/lib/python3.8/site-packages/keras/preprocessing/image.py", line 1648, in flow_from_directory
    return DirectoryIterator(
  File "/Users/sushraireddy/Desktop/Kidney-Disease-Classfication/kidney310/lib/python3.8/site-packages/keras/preprocessing/image.py", line 563, in __init__
    for subdir in sorted(os.listdir(directory)):
FileNotFoundError: [Errno 2] No such file or directory: 'artifacts/data_ingestion/kidney-ct-scan-image'
[2025-06-07 23:34:47,226: INFO: __init__: Welcome to custom log]
[2025-06-07 23:34:51,460: INFO: main: >>>>> stage Data Ingestion stage started <<<<<]
[2025-06-07 23:34:51,462: INFO: common: yaml file: config/config.yaml loaded successfully]
[2025-06-07 23:34:51,463: INFO: common: yaml file: params.yaml loaded successfully]
[2025-06-07 23:34:51,464: INFO: common: created directory at: artifacts]
[2025-06-07 23:34:51,464: INFO: common: created directory at: artifacts/data_ingestion]
[2025-06-07 23:34:51,464: INFO: data_ingestion: Downloading data from https://drive.google.com/file/d/1wqlI7hsen8Q7wpjzs3pUeGlDZKqci4W-/view?usp=sharing into file artifacts/data_ingestion/data.zip]
[2025-06-07 23:39:04,917: INFO: data_ingestion: Downloaded data from https://drive.google.com/file/d/1wqlI7hsen8Q7wpjzs3pUeGlDZKqci4W-/view?usp=sharing into file artifacts/data_ingestion/data.zip]
[2025-06-07 23:39:14,700: INFO: main: >>>>> stage Data Ingestion stage completed <<<<<

x==========x]
[2025-06-07 23:39:14,701: INFO: main: >>>>> stage Prepare Base Model Stage started <<<<<]
[2025-06-07 23:39:14,705: INFO: common: yaml file: config/config.yaml loaded successfully]
[2025-06-07 23:39:14,706: INFO: common: yaml file: params.yaml loaded successfully]
[2025-06-07 23:39:14,706: INFO: common: created directory at: artifacts]
[2025-06-07 23:39:14,706: INFO: common: created directory at: artifacts/prepare_base_model]
[2025-06-07 23:39:15,674: WARNING: saving_utils: Compiled the loaded model, but the compiled metrics have yet to be built. `model.compile_metrics` will be empty until you train or evaluate the model.]
[2025-06-07 23:39:15,782: WARNING: optimizer: At this time, the v2.11+ optimizer `tf.keras.optimizers.Adam` runs slowly on M1/M2 Macs, please use the legacy Keras optimizer instead, located at `tf.keras.optimizers.legacy.Adam`.]
[2025-06-07 23:39:15,785: WARNING: __init__: There is a known slowdown when using v2.11+ Keras optimizers on M1/M2 Macs. Falling back to the legacy Keras optimizer, i.e., `tf.keras.optimizers.legacy.Adam`.]
[2025-06-07 23:39:15,878: INFO: main: >>>>> stage Prepare Base Model Stage completed <<<<<

x==========x]
[2025-06-07 23:39:15,878: INFO: main: >>>>> stage Model Training Stage started <<<<<]
[2025-06-07 23:39:15,880: INFO: common: yaml file: config/config.yaml loaded successfully]
[2025-06-07 23:39:15,881: INFO: common: yaml file: params.yaml loaded successfully]
[2025-06-07 23:39:15,881: INFO: common: created directory at: artifacts]
[2025-06-07 23:39:15,882: INFO: common: created directory at: artifacts/training]
[2025-06-07 23:39:18,193: ERROR: main: cannot identify image file <_io.BytesIO object at 0x31c648f40>]
Traceback (most recent call last):
  File "main.py", line 31, in <module>
    model_training_pipeline.main()
  File "/Users/sushraireddy/Desktop/Kidney-Disease-Classfication/Kidney-Disease-Classfication/src/cnnClassifier/pipeline/stage_03_model_training.py", line 16, in main
    training.train()
  File "/Users/sushraireddy/Desktop/Kidney-Disease-Classfication/Kidney-Disease-Classfication/src/cnnClassifier/components/model_training.py", line 80, in train
    self.model.fit(
  File "/Users/sushraireddy/Desktop/Kidney-Disease-Classfication/kidney310/lib/python3.8/site-packages/keras/utils/traceback_utils.py", line 70, in error_handler
    raise e.with_traceback(filtered_tb) from None
  File "/Users/sushraireddy/Desktop/Kidney-Disease-Classfication/kidney310/lib/python3.8/site-packages/PIL/Image.py", line 3498, in open
    raise UnidentifiedImageError(msg)
PIL.UnidentifiedImageError: cannot identify image file <_io.BytesIO object at 0x31c648f40>
[2025-06-07 23:49:51,303: INFO: __init__: Welcome to custom log]
[2025-06-08 12:17:57,846: INFO: __init__: Welcome to custom log]
[2025-06-08 12:18:01,997: INFO: main: >>>>> stage Data Ingestion stage started <<<<<]
[2025-06-08 12:18:01,999: INFO: common: yaml file: config/config.yaml loaded successfully]
[2025-06-08 12:18:02,000: INFO: common: yaml file: params.yaml loaded successfully]
[2025-06-08 12:18:02,000: INFO: common: created directory at: artifacts]
[2025-06-08 12:18:02,000: INFO: common: created directory at: artifacts/data_ingestion]
[2025-06-08 12:18:02,001: INFO: data_ingestion: Downloading data from https://drive.google.com/file/d/1wqlI7hsen8Q7wpjzs3pUeGlDZKqci4W-/view?usp=sharing into file artifacts/data_ingestion/data.zip]
[2025-06-08 12:18:31,067: INFO: __init__: Welcome to custom log]
[2025-06-08 12:18:34,100: INFO: main: >>>>> stage Data Ingestion stage started <<<<<]
[2025-06-08 12:18:34,101: INFO: common: yaml file: config/config.yaml loaded successfully]
[2025-06-08 12:18:34,102: INFO: common: yaml file: params.yaml loaded successfully]
[2025-06-08 12:18:34,103: INFO: common: created directory at: artifacts]
[2025-06-08 12:18:34,103: INFO: common: created directory at: artifacts/data_ingestion]
[2025-06-08 12:18:34,103: INFO: data_ingestion: Downloading data from https://drive.google.com/file/d/1wqlI7hsen8Q7wpjzs3pUeGlDZKqci4W-/view?usp=sharing into file artifacts/data_ingestion/data.zip]
[2025-06-08 12:23:21,816: INFO: data_ingestion: Downloaded data from https://drive.google.com/file/d/1wqlI7hsen8Q7wpjzs3pUeGlDZKqci4W-/view?usp=sharing into file artifacts/data_ingestion/data.zip]
[2025-06-08 12:23:32,507: INFO: main: >>>>> stage Data Ingestion stage completed <<<<<

x==========x]
[2025-06-08 12:23:32,508: INFO: main: >>>>> stage Prepare Base Model Stage started <<<<<]
[2025-06-08 12:23:32,513: INFO: common: yaml file: config/config.yaml loaded successfully]
[2025-06-08 12:23:32,515: INFO: common: yaml file: params.yaml loaded successfully]
[2025-06-08 12:23:32,516: INFO: common: created directory at: artifacts]
[2025-06-08 12:23:32,516: INFO: common: created directory at: artifacts/prepare_base_model]
[2025-06-08 12:23:34,438: WARNING: saving_utils: Compiled the loaded model, but the compiled metrics have yet to be built. `model.compile_metrics` will be empty until you train or evaluate the model.]
[2025-06-08 12:23:34,776: WARNING: optimizer: At this time, the v2.11+ optimizer `tf.keras.optimizers.Adam` runs slowly on M1/M2 Macs, please use the legacy Keras optimizer instead, located at `tf.keras.optimizers.legacy.Adam`.]
[2025-06-08 12:23:34,785: WARNING: __init__: There is a known slowdown when using v2.11+ Keras optimizers on M1/M2 Macs. Falling back to the legacy Keras optimizer, i.e., `tf.keras.optimizers.legacy.Adam`.]
[2025-06-08 12:23:34,967: INFO: main: >>>>> stage Prepare Base Model Stage completed <<<<<

x==========x]
[2025-06-08 12:23:34,967: INFO: main: >>>>> stage Model Training Stage started <<<<<]
[2025-06-08 12:23:34,971: INFO: common: yaml file: config/config.yaml loaded successfully]
[2025-06-08 12:23:34,975: INFO: common: yaml file: params.yaml loaded successfully]
[2025-06-08 12:23:34,975: INFO: common: created directory at: artifacts]
[2025-06-08 12:23:34,976: INFO: common: created directory at: artifacts/training]
[2025-06-08 12:23:35,376: ERROR: main: flow_from_directory() got an unexpected keyword argument 'ignore_bad_files']
Traceback (most recent call last):
  File "main.py", line 31, in <module>
    model_training_pipeline.main()
  File "/Users/sushraireddy/Desktop/Kidney-Disease-Classfication/Kidney-Disease-Classfication/src/cnnClassifier/pipeline/stage_03_model_training.py", line 15, in main
    training.train_valid_generator()
  File "/Users/sushraireddy/Desktop/Kidney-Disease-Classfication/Kidney-Disease-Classfication/src/cnnClassifier/components/model_training.py", line 40, in train_valid_generator
    self.valid_generator = valid_datagenerator.flow_from_directory(
TypeError: flow_from_directory() got an unexpected keyword argument 'ignore_bad_files'
[2025-06-08 12:29:46,868: INFO: __init__: Welcome to custom log]
[2025-06-08 12:29:50,925: INFO: main: >>>>> stage Data Ingestion stage started <<<<<]
[2025-06-08 12:29:50,927: INFO: common: yaml file: config/config.yaml loaded successfully]
[2025-06-08 12:29:50,928: INFO: common: yaml file: params.yaml loaded successfully]
[2025-06-08 12:29:50,928: INFO: common: created directory at: artifacts]
[2025-06-08 12:29:50,928: INFO: common: created directory at: artifacts/data_ingestion]
[2025-06-08 12:29:50,929: INFO: data_ingestion: Downloading data from https://drive.google.com/file/d/1wqlI7hsen8Q7wpjzs3pUeGlDZKqci4W-/view?usp=sharing into file artifacts/data_ingestion/data.zip]
[2025-06-08 12:34:17,375: INFO: data_ingestion: Downloaded data from https://drive.google.com/file/d/1wqlI7hsen8Q7wpjzs3pUeGlDZKqci4W-/view?usp=sharing into file artifacts/data_ingestion/data.zip]
[2025-06-08 12:34:29,099: INFO: main: >>>>> stage Data Ingestion stage completed <<<<<

x==========x]
[2025-06-08 12:34:29,100: INFO: main: >>>>> stage Prepare Base Model Stage started <<<<<]
[2025-06-08 12:34:29,104: INFO: common: yaml file: config/config.yaml loaded successfully]
[2025-06-08 12:34:29,106: INFO: common: yaml file: params.yaml loaded successfully]
[2025-06-08 12:34:29,107: INFO: common: created directory at: artifacts]
[2025-06-08 12:34:29,107: INFO: common: created directory at: artifacts/prepare_base_model]
[2025-06-08 12:34:30,183: WARNING: saving_utils: Compiled the loaded model, but the compiled metrics have yet to be built. `model.compile_metrics` will be empty until you train or evaluate the model.]
[2025-06-08 12:34:30,311: WARNING: optimizer: At this time, the v2.11+ optimizer `tf.keras.optimizers.Adam` runs slowly on M1/M2 Macs, please use the legacy Keras optimizer instead, located at `tf.keras.optimizers.legacy.Adam`.]
[2025-06-08 12:34:30,314: WARNING: __init__: There is a known slowdown when using v2.11+ Keras optimizers on M1/M2 Macs. Falling back to the legacy Keras optimizer, i.e., `tf.keras.optimizers.legacy.Adam`.]
[2025-06-08 12:34:30,388: INFO: main: >>>>> stage Prepare Base Model Stage completed <<<<<

x==========x]
[2025-06-08 12:34:30,389: INFO: main: >>>>> stage Model Training Stage started <<<<<]
[2025-06-08 12:34:30,391: INFO: common: yaml file: config/config.yaml loaded successfully]
[2025-06-08 12:34:30,392: INFO: common: yaml file: params.yaml loaded successfully]
[2025-06-08 12:34:30,392: INFO: common: created directory at: artifacts]
[2025-06-08 12:34:30,392: INFO: common: created directory at: artifacts/training]
[2025-06-08 12:39:38,225: INFO: main: >>>>> stage Model Training Stage completed <<<<<

x==========x]
[2025-06-09 23:13:28,225: INFO: __init__: Welcome to custom log]
[2025-06-09 23:31:20,841: INFO: __init__: Welcome to custom log]
[2025-06-09 23:56:18,392: INFO: common: yaml file: config/config.yaml loaded successfully]
[2025-06-09 23:56:18,399: INFO: common: yaml file: params.yaml loaded successfully]
[2025-06-09 23:56:18,400: INFO: common: created directory at: artifacts]
[2025-06-09 23:59:10,737: INFO: __init__: Welcome to custom log]
[2025-06-09 23:59:22,466: INFO: common: yaml file: config/config.yaml loaded successfully]
[2025-06-09 23:59:22,562: INFO: common: yaml file: params.yaml loaded successfully]
[2025-06-09 23:59:22,563: INFO: common: created directory at: artifacts]
[2025-06-10 11:47:29,595: INFO: __init__: Welcome to custom log]
[2025-06-10 11:47:40,549: INFO: common: yaml file: config/config.yaml loaded successfully]
[2025-06-10 11:47:40,553: INFO: common: yaml file: params.yaml loaded successfully]
[2025-06-10 11:47:40,555: INFO: common: created directory at: artifacts]
[2025-06-10 11:49:03,733: INFO: common: json file saved at: scores.json]
[2025-06-10 11:49:03,735: INFO: common: json file saved at: scores.json]
[2025-06-10 11:55:53,727: INFO: common: yaml file: config/config.yaml loaded successfully]
[2025-06-10 11:55:53,734: INFO: common: yaml file: params.yaml loaded successfully]
[2025-06-10 11:55:53,738: INFO: common: created directory at: artifacts]
[2025-06-10 11:57:38,675: INFO: common: json file saved at: scores.json]
[2025-06-10 11:57:38,680: INFO: common: json file saved at: scores.json]
[2025-06-10 11:57:38,789: WARNING: connectionpool: Retrying (Retry(total=4, connect=5, read=4, redirect=5, status=5)) after connection broken by 'ConnectionResetError(54, 'Connection reset by peer')': /sushrai1/Kidney-Disease-Classfication.mlflow/api/2.0/mlflow/runs/create]
[2025-06-10 13:51:41,256: INFO: common: yaml file: config/config.yaml loaded successfully]
[2025-06-10 13:51:41,260: INFO: common: yaml file: params.yaml loaded successfully]
[2025-06-10 13:51:41,261: INFO: common: created directory at: artifacts]
[2025-06-10 13:54:10,519: INFO: common: json file saved at: scores.json]
[2025-06-10 13:54:18,490: INFO: _client: HTTP Request: POST https://dagshub.com/login/oauth/middleman "HTTP/1.1 200 OK"]
[2025-06-10 13:54:18,923: INFO: _client: HTTP Request: POST https://dagshub.com/login/oauth/access_token "HTTP/1.1 200 OK"]
[2025-06-10 13:54:19,334: INFO: _client: HTTP Request: GET https://dagshub.com/api/v1/user "HTTP/1.1 200 OK"]
[2025-06-10 13:54:19,349: INFO: helpers: Accessing as sushrai1]
[2025-06-10 13:54:19,774: INFO: _client: HTTP Request: GET https://dagshub.com/api/v1/repos/sushrai1/Kidney-Disease-Classfication "HTTP/1.1 200 OK"]
[2025-06-10 13:54:20,219: INFO: _client: HTTP Request: GET https://dagshub.com/api/v1/user "HTTP/1.1 200 OK"]
[2025-06-10 13:54:20,229: INFO: helpers: Initialized MLflow to track repo "sushrai1/Kidney-Disease-Classfication"]
[2025-06-10 13:54:20,231: INFO: helpers: Repository sushrai1/Kidney-Disease-Classfication initialized!]
[2025-06-10 13:54:20,308: WARNING: connectionpool: Retrying (Retry(total=4, connect=5, read=4, redirect=5, status=5)) after connection broken by 'ConnectionResetError(54, 'Connection reset by peer')': /sushrai1/Kidney-Disease-Classfication.mlflow/api/2.0/mlflow/runs/create]
[2025-06-10 13:54:22,496: WARNING: save: Found untraced functions such as _jit_compiled_convolution_op, _jit_compiled_convolution_op, _jit_compiled_convolution_op, _jit_compiled_convolution_op, _jit_compiled_convolution_op while saving (showing 5 of 13). These functions will not be directly callable after loading.]
[2025-06-10 13:54:23,747: INFO: builder_impl: Assets written to: /var/folders/dq/vww2cj157s37y2q65dgqkq740000gn/T/tmp8gal3tzu/model/data/model/assets]
[2025-06-10 23:09:58,552: INFO: __init__: Welcome to custom log]
[2025-06-10 23:15:14,711: INFO: __init__: Welcome to custom log]
[2025-06-10 23:15:19,405: INFO: main: >>>>> stage Data Ingestion stage started <<<<<]
[2025-06-10 23:15:19,407: INFO: common: yaml file: config/config.yaml loaded successfully]
[2025-06-10 23:15:19,408: INFO: common: yaml file: params.yaml loaded successfully]
[2025-06-10 23:15:19,408: INFO: common: created directory at: artifacts]
[2025-06-10 23:15:19,408: INFO: common: created directory at: artifacts/data_ingestion]
[2025-06-10 23:15:19,408: INFO: data_ingestion: Downloading data from https://drive.google.com/file/d/1wqlI7hsen8Q7wpjzs3pUeGlDZKqci4W-/view?usp=sharing into file artifacts/data_ingestion/data.zip]
[2025-06-10 23:17:01,723: INFO: data_ingestion: Downloaded data from https://drive.google.com/file/d/1wqlI7hsen8Q7wpjzs3pUeGlDZKqci4W-/view?usp=sharing into file artifacts/data_ingestion/data.zip]
[2025-06-10 23:17:15,533: INFO: main: >>>>> stage Data Ingestion stage completed <<<<<

x==========x]
[2025-06-10 23:17:15,535: INFO: main: >>>>> stage Prepare Base Model Stage started <<<<<]
[2025-06-10 23:17:15,541: INFO: common: yaml file: config/config.yaml loaded successfully]
[2025-06-10 23:17:15,545: INFO: common: yaml file: params.yaml loaded successfully]
[2025-06-10 23:17:15,546: INFO: common: created directory at: artifacts]
[2025-06-10 23:17:15,546: INFO: common: created directory at: artifacts/prepare_base_model]
[2025-06-10 23:17:16,553: WARNING: saving_utils: Compiled the loaded model, but the compiled metrics have yet to be built. `model.compile_metrics` will be empty until you train or evaluate the model.]
[2025-06-10 23:17:16,689: WARNING: optimizer: At this time, the v2.11+ optimizer `tf.keras.optimizers.Adam` runs slowly on M1/M2 Macs, please use the legacy Keras optimizer instead, located at `tf.keras.optimizers.legacy.Adam`.]
[2025-06-10 23:17:16,692: WARNING: __init__: There is a known slowdown when using v2.11+ Keras optimizers on M1/M2 Macs. Falling back to the legacy Keras optimizer, i.e., `tf.keras.optimizers.legacy.Adam`.]
[2025-06-10 23:17:16,788: INFO: main: >>>>> stage Prepare Base Model Stage completed <<<<<

x==========x]
[2025-06-10 23:17:16,789: INFO: main: >>>>> stage Model Training Stage started <<<<<]
[2025-06-10 23:17:16,791: INFO: common: yaml file: config/config.yaml loaded successfully]
[2025-06-10 23:17:16,793: INFO: common: yaml file: params.yaml loaded successfully]
[2025-06-10 23:17:16,793: INFO: common: created directory at: artifacts]
[2025-06-10 23:17:16,793: INFO: common: created directory at: artifacts/training]
[2025-06-10 23:35:33,072: INFO: main: >>>>> stage Model Training Stage completed <<<<<

x==========x]
[2025-06-10 23:35:33,074: INFO: main: >>>>> stage Model Evaluation Stage started <<<<<]
[2025-06-10 23:35:33,079: INFO: common: yaml file: config/config.yaml loaded successfully]
[2025-06-10 23:35:33,081: INFO: common: yaml file: params.yaml loaded successfully]
[2025-06-10 23:35:33,081: INFO: common: created directory at: artifacts]
[2025-06-10 23:37:25,138: INFO: common: json file saved at: scores.json]
[2025-06-10 23:37:25,673: INFO: _client: HTTP Request: GET https://dagshub.com/api/v1/user "HTTP/1.1 200 OK"]
[2025-06-10 23:37:25,712: INFO: helpers: Accessing as sushrai1]
[2025-06-10 23:37:26,299: INFO: _client: HTTP Request: GET https://dagshub.com/api/v1/repos/sushrai1/Kidney-Disease-Classfication "HTTP/1.1 200 OK"]
[2025-06-10 23:37:26,711: INFO: _client: HTTP Request: GET https://dagshub.com/api/v1/user "HTTP/1.1 200 OK"]
[2025-06-10 23:37:26,718: INFO: helpers: Initialized MLflow to track repo "sushrai1/Kidney-Disease-Classfication"]
[2025-06-10 23:37:26,719: INFO: helpers: Repository sushrai1/Kidney-Disease-Classfication initialized!]
[2025-06-10 23:37:29,189: WARNING: save: Found untraced functions such as _jit_compiled_convolution_op, _jit_compiled_convolution_op, _jit_compiled_convolution_op, _jit_compiled_convolution_op, _jit_compiled_convolution_op while saving (showing 5 of 13). These functions will not be directly callable after loading.]
[2025-06-10 23:37:29,683: INFO: builder_impl: Assets written to: /var/folders/dq/vww2cj157s37y2q65dgqkq740000gn/T/tmpjzn7ttnc/model/data/model/assets]
[2025-06-10 23:38:04,088: INFO: main: >>>>> stage Model Evaluation Stage completed <<<<<

x==========x]
